Workbook

Sheet Summary View
A1: Stage | B1: Total | C1: %
A2: Total in Pipeline | B2: =SUM(B3+B4+B6) -> 5
A3: Currently Account Managed | B3: =COUNTIF(GTT_Leads[Stage], "Account Managed") -> 1 | C3: =B3/B2 -> 0.2
A4: Cleared (To be pitched) | B4: {=SUM(COUNTIF(GTT_Leads[Priority], {2,3,4,5,6,7}))} -> 3 | C4: =B4/B2 -> 0.6
A5: Pending Clearance | B5: =COUNTIF(GTT_Leads[Stage], "Pending") -> 0 | C5: =B5/B2 -> 0
A6: Successfully Converted | B6: =COUNTIF(GTT_Leads[Stage], "Closed") -> 1 | C6: =B6/B2 -> 0.2
A8: Prioritisation | B8: Green | C8: Amber | D8: Red
A9: Likelihood of success RAG | B9: =COUNTIFS('GTT Leads'!G:G, "Green", 'GTT Leads'!E:E,">=1",'GTT Leads'!E:E,"<=7") -> 2 | C9: =COUNTIFS('GTT Leads'!G:G, "Amber", 'GTT Leads'!E:E,">=1",'GTT Leads'!E:E,"<=7") -> 2 | D9: =COUNTIFS('GTT Leads'!G:G, "Red", 'GTT Leads'!E:E,">=1",'GTT Leads'!E:E,"<=7") -> 0
A10: Strength of relationship RAG | B10: =COUNTIFS('GTT Leads'!I:I, "Green", 'GTT Leads'!E:E,">=1",'GTT Leads'!E:E,"<=7") -> 2 | C10: =COUNTIFS('GTT Leads'!I:I, "Amber", 'GTT Leads'!E:E,">=1",'GTT Leads'!E:E,"<=7") -> 1 | D10: =COUNTIFS('GTT Leads'!H:H, "Red", 'GTT Leads'!D:D,">=1",'GTT Leads'!D:D,"<=7") -> 0
A12: Source of referral | B12: Total | C12: %
A13: Post-USA | B13: =COUNTIFS(GTT_Leads[Source of lead], "Post - USA", GTT_Leads[Priority], ">=1", GTT_Leads[Priority], "<=8") -> 0 | C13: =B13/B$2 -> 0
A14: Post-Brazil | B14: =COUNTIFS(GTT_Leads[Source of lead], "Post-Brazil", GTT_Leads[Priority], ">=1", GTT_Leads[Priority], "<=8") -> 0 | C14: =B14/B2 -> 0
A15: Number 10 | B15: =COUNTIFS(GTT_Leads[Source of lead], "Number 10", GTT_Leads[Priority], ">=1", GTT_Leads[Priority], "<=8") -> 1 | C15: =B15/B$2 -> 0.2
A16: OGD | B16: =COUNTIFS(GTT_Leads[Source of lead], "OGD", GTT_Leads[Priority], ">=1", GTT_Leads[Priority], "<=8") -> 1 | C16: =B16/B4 -> 0.33333333
A17: External | B17: =COUNTIFS(GTT_Leads[Source of lead], "External", GTT_Leads[Priority], ">=1", GTT_Leads[Priority], "<=7") -> 1 | C17: =B17/B$2 -> 0.2
A18: DBT/OfI | B18: =COUNTIFS(GTT_Leads[Source of lead], "DBT/OfI", GTT_Leads[Priority], ">=1", GTT_Leads[Priority], "<=8") -> 1 | C18: =B18/B2 -> 0.2
A19: Post-India | B19: =COUNTIFS(GTT_Leads[Source of lead], "Post-India", GTT_Leads[Priority], ">=1", GTT_Leads[Priority], "<=8") -> 0 | C19: =B19/B$2 -> 0
A20: Post-Singapore | B20: =COUNTIFS(GTT_Leads[Source of lead], "Post-Singapore", GTT_Leads[Priority], ">=1", GTT_Leads[Priority], "<=8") -> 0 | C20: =B20/B2 -> 0
A22: Current residence | B22: Total | C22: %
A23: USA | B23: =COUNTIFS(GTT_Leads[Current Residency], "*USA*", GTT_Leads[Priority],">=1",GTT_Leads[Priority],"<=8") -> 2 | C23: =B23/B$2 -> 0.4
A24: India | B24: =COUNTIFS(GTT_Leads[Current Residency], "*India*", GTT_Leads[Priority],">=1",GTT_Leads[Priority],"<=8") -> 1 | C24: =B24/B$2 -> 0.2
A25: UK | B25: =COUNTIFS(GTT_Leads[Current Residency], "*UK*", GTT_Leads[Priority],">=1",GTT_Leads[Priority],"<=8") -> 1 | C25: =B25/B$2 -> 0.2
A26: Singapore | B26: =COUNTIFS(GTT_Leads[Current Residency], "*Singapore*", GTT_Leads[Priority],">=1",GTT_Leads[Priority],"<=8") -> 0 | C26: =B26/B$2 -> 0
A27: Brazil | B27: =COUNTIFS(GTT_Leads[Current Residency], "*Brazil*", GTT_Leads[Priority],">=1",GTT_Leads[Priority],"<=8") -> 0 | C27: =B27/B$2 -> 0
A28: Americas (Other) | B28: =COUNTIFS(GTT_Leads[Current Residency], "*Canada*", GTT_Leads[Priority],">=1",GTT_Leads[Priority],"<=8") -> 0 | C28: =B28/B$2 -> 0
A29: Europe | B29: {=SUM(COUNTIFS(GTT_Leads[Current Residency],{"*Finland*","*Denmark*","*France*","*Germany*","*Netherlands*"},GTT_Leads[Priority],">=1",GTT_Leads[Priority],"<=8"))} -> 1 | C29: =B29/B$2 -> 0.2
A30: Asia (Other) | B30: {=SUM(COUNTIFS(GTT_Leads[Current Residency],{"*Australia*","*Taiwan*"},GTT_Leads[Priority],">=1",GTT_Leads[Priority],"<=8"))} -> 0 | C30: =B30/B$2 -> 0
A31: Other | B31: =B2-SUM(B23:B30) -> 0 | C31: =B31/B$2 -> 0
A33: Criteria | B33: Total | C33: %
A34: UHNWI | B34: =COUNTIFS(GTT_Leads[Criteria], "*HNWI*",GTT_Leads[Priority],">=1",GTT_Leads[Priority],"<=8") -> 1 | C34: =B34/B$2 -> 0.2
A35: Investor | B35: =COUNTIFS(GTT_Leads[Criteria], "*Investor*",GTT_Leads[Priority],">=1",GTT_Leads[Priority],"<=8") -> 0 | C35: =B35/B$2 -> 0
A36: Digital Technologies Talent | B36: =COUNTIFS(GTT_Leads[Criteria], "*Digital*",GTT_Leads[Priority],">=1",GTT_Leads[Priority],"<=8") -> 2 | C36: =B36/B$2 -> 0.4
A37: Life Sciences Talent | B37: =COUNTIFS(GTT_Leads[Criteria], "*Life*",GTT_Leads[Priority],">=1",GTT_Leads[Priority],"<=8") -> 1 | C37: =B37/B$2 -> 0.2
A38: Clean Energies Talent | B38: =COUNTIFS(GTT_Leads[Criteria], "*Clean*",GTT_Leads[Priority],">=1",GTT_Leads[Priority],"<=8") -> 1 | C38: =B38/B$2 -> 0.2
A40: GTT Priority Sectors | B40: Total | C40: %
A41: Life Sciences | B41: =COUNTIFS(GTT_Leads[GTT Priority Sector], "*Life Sciences*",GTT_Leads[Priority],">=1",GTT_Leads[Priority],"<=8") -> 1 | C41: =B41/B$2 -> 0.2
A42: Clean Energy | B42: =COUNTIFS(GTT_Leads[GTT Priority Sector], "*clean*",GTT_Leads[Priority],">=1",GTT_Leads[Priority],"<=8") -> 1 | C42: =B42/B$2 -> 0.2
A43: Digital & Tech | B43: =COUNTIFS(GTT_Leads[GTT Priority Sector], "*tech*",GTT_Leads[Priority],">=1",GTT_Leads[Priority],"<=8") -> 0 | C43: =B43/B$2 -> 0
A44: AI | B44: =COUNTIFS(GTT_Leads[GTT Priority Sector], "*AI*",GTT_Leads[Priority],">=1",GTT_Leads[Priority],"<=8") -> 2 | C44: =B44/B$2 -> 0.4
A45: Pan-Economy Investors | B45: =COUNTIFS(GTT_Leads[GTT Priority Sector], "*investor*",GTT_Leads[Priority],">=1",GTT_Leads[Priority],"<=8") -> 1 | C45: =B45/B$2 -> 0.2
...

Sheet GTT Leads
A1: At a Glance | E1: Stage | K1: Stakeholders | N1: Further Info
A3: Name Link to AP if applicable | B3: Organisation | C3: Role | D3: Next Step | E3: Priority | F3: Stage | G3: Success RAG | H3: Full AM/ Light-touch | I3: Relationship RAG | J3: Background Check | K3: Relationship Holder | L3: GTT Account Manager | M3: Source of lead | N3: Origin Date | O3: Link to Data Hub (Where Applicable) | P3: Current Residency | Q3: Further Background | R3: Nationality | S3: Criteria | T3: GTT Priority Sector | U3: Type of Individual
A4: Joe Green | B4: Wind Power Inc | C4: CEO | D4: Waiting on visa update from HO | E4: {=_xlfn.LET(_xlpm.stage,GTT_Leads[[#This Row],[Stage]],_xlpm.s,GTT_Leads[[#This Row],[Success RAG]],_xlpm.r,GTT_Leads[[#This Row],[Relationship RAG]],_xlfn.IFS(_xlpm.stage="Account Managed",1,AND(_xlpm.stage="Cleared",_xlpm.s="Green",_xlpm.r="Green"),2,AND(_xlpm.stage="Cleared",_xlpm.s="Green",_xlpm.r="Amber"),3,AND(_xlpm.stage="Cleared",_xlpm.s="Amber",_xlpm.r="Green"),4,AND(_xlpm.stage="Cleared",_xlpm.s="Green",_xlpm.r="Red"),5,AND(_xlpm.stage="Cleared",_xlpm.s="Amber",_xlpm.r="Amber"),6,AND(_xlpm.stage="Cleared",_xlpm.s="Amber",_xlpm.r="Red"),7,_xlpm.stage="Closed",8,AND(_xlpm.stage="Cleared",_xlpm.s="Red",_xlpm.r="Red"),9,TRUE,""))} -> 1 | F4: Account Managed | G4: Green | H4: Full | I4: Green | J4: Clear | K4: DSIT | L4: Katie | M4: OGD | N4: 46181 | O4: Link | P4: Denmark | Q4: Joe is setting up new UK office. Has UK lawyer already and has applied for GTV. GTT is helping to expedite. | R4: Danish | S4: Clean Energy | T4: Clean Energy | U4: C-Suite
A5: Anne Rose | B5: Bio Capital | C5: Investor | D5: Henry to set up intro call | E5: {=_xlfn.LET( _xlpm.stage, GTT_Leads[[#This Row],[Stage]], _xlpm.s, GTT_Leads[[#This Row],[Success RAG]], _xlpm.r, GTT_Leads[[#This Row],[Relationship RAG]], _xlfn.IFS( _xlpm.stage="Account Managed", 1, AND(_xlpm.stage="Cleared", _xlpm.s="Green", _xlpm.r="Green"), 2, AND(_xlpm.stage="Cleared", _xlpm.s="Green", _xlpm.r="Amber"), 3, AND(_xlpm.stage="Cleared", _xlpm.s="Amber", _xlpm.r="Green"), 4, AND(_xlpm.stage="Cleared", _xlpm.s="Green", _xlpm.r="Red"), 5, AND(_xlpm.stage="Cleared", _xlpm.s="Amber", _xlpm.r="Amber"), 6, AND(_xlpm.stage="Cleared", _xlpm.s="Amber", _xlpm.r="Red"), 7, AND(_xlpm.stage="Cleared", _xlpm.s="Red", _xlpm.r="Red"), 8, TRUE, "" ) )} -> 2 | F5: Cleared | G5: Green | H5: Light | I5: Green | J5: Clear | K5: No10 | L5: Henry | M5: Number 10 | N5: 46151 | O5: Link | P5: India | Q5: Reached out to No10 for help getting additional CoS. | R5: Indian | S5: Life Sciences | T5: Life Sciences | U5: Investor
A6: Lea Black | B6: Black Family Investments | C6: Chairman | D6: John Edwards to intro Katie | E6: {=_xlfn.LET(_xlpm.stage,GTT_Leads[[#This Row],[Stage]],_xlpm.s,GTT_Leads[[#This Row],[Success RAG]],_xlpm.r,GTT_Leads[[#This Row],[Relationship RAG]],_xlfn.IFS(_xlpm.stage="Account Managed",1,AND(_xlpm.stage="Cleared",_xlpm.s="Green",_xlpm.r="Green"),2,AND(_xlpm.stage="Cleared",_xlpm.s="Green",_xlpm.r="Amber"),3,AND(_xlpm.stage="Cleared",_xlpm.s="Amber",_xlpm.r="Green"),4,AND(_xlpm.stage="Cleared",_xlpm.s="Green",_xlpm.r="Red"),5,AND(_xlpm.stage="Cleared",_xlpm.s="Amber",_xlpm.r="Amber"),6,AND(_xlpm.stage="Cleared",_xlpm.s="Amber",_xlpm.r="Red"),7,_xlpm.stage="Closed",8,AND(_xlpm.stage="Cleared",_xlpm.s="Red",_xlpm.r="Red"),9,TRUE,""))} -> 6 | F6: Cleared | G6: Amber | H6: Full | I6: Amber | J6: Clear | K6: John Edwards | L6: Katie | M6: DBT/OfI | N6: 46189 | O6: No link | P6: UK | Q6: John E met Lea at an event in London. She is considering moving back to US but not yet decided. | R6: American | S6: UHNWI | T6: Pan Economy Investor | U6: HNWI
A7: Ben White | B7: Smart Applications | C7: Head of Research | D7: Not yet contacted- find way of getting in touch | E7: {=_xlfn.LET(_xlpm.stage,GTT_Leads[[#This Row],[Stage]],_xlpm.s,GTT_Leads[[#This Row],[Success RAG]],_xlpm.r,GTT_Leads[[#This Row],[Relationship RAG]],_xlfn.IFS(_xlpm.stage="Account Managed",1,AND(_xlpm.stage="Cleared",_xlpm.s="Green",_xlpm.r="Green"),2,AND(_xlpm.stage="Cleared",_xlpm.s="Green",_xlpm.r="Amber"),3,AND(_xlpm.stage="Cleared",_xlpm.s="Amber",_xlpm.r="Green"),4,AND(_xlpm.stage="Cleared",_xlpm.s="Green",_xlpm.r="Red"),5,AND(_xlpm.stage="Cleared",_xlpm.s="Amber",_xlpm.r="Amber"),6,AND(_xlpm.stage="Cleared",_xlpm.s="Amber",_xlpm.r="Red"),7,_xlpm.stage="Closed",8,AND(_xlpm.stage="Cleared",_xlpm.s="Red",_xlpm.r="Red"),9,TRUE,""))} -> 7 | F7: Cleared | G7: Amber | H7: Full | I7: Red | J7: Clear | K7: Mary | L7: Katie | M7: External | N7: 46189 | O7: Link | P7: USA | Q7: Mentioned to Mary by another external company as a potential target. No known relationships within Government so need to find an introduction. | R7: American | S7: Digital/Tech | T7: AI | U7: Researcher
A8: Mike Smith | B8: Cognita AI | C8: Co-founder | D8: Successfully converted | E8: {=_xlfn.LET(_xlpm.stage,GTT_Leads[[#This Row],[Stage]],_xlpm.s,GTT_Leads[[#This Row],[Success RAG]],_xlpm.r,GTT_Leads[[#This Row],[Relationship RAG]],_xlfn.IFS(_xlpm.stage="Account Managed",1,AND(_xlpm.stage="Cleared",_xlpm.s="Green",_xlpm.r="Green"),2,AND(_xlpm.stage="Cleared",_xlpm.s="Green",_xlpm.r="Amber"),3,AND(_xlpm.stage="Cleared",_xlpm.s="Amber",_xlpm.r="Green"),4,AND(_xlpm.stage="Cleared",_xlpm.s="Green",_xlpm.r="Red"),5,AND(_xlpm.stage="Cleared",_xlpm.s="Amber",_xlpm.r="Amber"),6,AND(_xlpm.stage="Cleared",_xlpm.s="Amber",_xlpm.r="Red"),7,_xlpm.stage="Closed",8,AND(_xlpm.stage="Cleared",_xlpm.s="Red",_xlpm.r="Red"),9,TRUE,""))} -> 8 | F8: Closed | G8: Green | H8: Full | I8: Green | J8: Clear | K8: Mary | L8: Henry | M8: Post-USA | N8: 46184 | O8: Link | P8: USA | Q8: Interested in relocating with family to UK and establishing London as Rest of World HQ for the business. | R8: American | S8: Digital/Tech | T8: AI | U8: Founder

Sheet Closed Accounts Summary
A1: This sheet captures the nature of support that individuals receieved from the Taskforce and what issues they raised.
A3: Name And link to account plan for further info | B3: Organisation | C3: Role | D3: Date Closed | E3: Account Manager | F3: Catergory of Issue Raised Visas, Tax, Capital Markets, Banking, Research Incentives, Regulation | G3: Light Touch/ Full Support | H3: Details Details of the issue faced by the individual and which areas of HMG it may relate to | I3: Solution offered What solutions were provided by the GTT AM function and what OGDs (if any) did you have to work with and how? | J3: Was issue resolved? [Y/N/Partially] – if N/partially, provide details | K3: Overall Outcome Current status of individual. Did they relocate to the UK or increase their presence here? | L3: Meets success criteria? | M3: Success Category | N3: Key Escalations Any key issues demonstrated by this case that we may want to escalate either internally or whith OGDs. | O3: GTT Promotion
A4: Mike Smith | B4: Cognita AI | C4: Co-founder | D4: 46214 | E4: Henry | F4: Visas, Business support | G4: Full | H4: Needed visas for himself and his family to relocate (wasn't sure which route to take and concerned abou timelines). Wanted connections to founder community and potential future investors to help him set up in London. Wanted ability to bring over top talent from the US to help set up new UK business. | I4: Introduced to UK lawyers who supported with visa. Expedited GTV application (after endorsement was secured) and family's visas. Invited to founder event with Tech Nation. Supported with getting skilled worker visa sponsor licence and visas for US talent. | J4: Yes | K4: Established UK office with 5 local hires and 3 relocated from US | L4: Y | M4: Full Relocation | N4: No | O4: Sharing press notice on new office opening with mention of GTT

Sheet Failed Leads
A1: Name | B1: Conmpany | C1: Reason for Failure
A2: Bob Baker | B2: One company | C2: Not GTT level seniority
A3: Harriet Butcher | B3: Another company | C3: High reputational risk

Sheet External Partners
A1: Service Providers Summary
A2: Agreed Partnerships
A3: Legal Services | B3: =COUNTIF(Table5[Sector], A3) -> 1
A4: Finance/Accounting | B4: =COUNTIF(Table5[Sector], A4) -> 1
A5: Investment | B5: =COUNTIF(Table5[Sector], A5) -> 0
A6: Real Estate | B6: =COUNTIF(Table5[Sector], A6) -> 1
A9: Name | B9: Organisation | C9: Title | D9: Stage | E9: Sector | F9: Customers | G9: Based | H9: Origin | I9: Background check | J9: Notes
A10: Joe Bloggs | B10: Bloggs, Clark, Smith | C10: Partner | D10: Partnership Agreed | E10: Legal Services | F10: Founders | G10: London | H10: OfI | I10: Cleared
A11: John Smith | B11: Finance Solutions | C11: Accountant | D11: Pitched | E11: Finance/Accounting | F11: Start-up businesses | G11: Manchester | H11: Met at event | I11: Cleared
A12: Jane Doe | B12: Homes Finder | C12: Head of Sales | D12: Pursuing Partnership | E12: Real Estate | F12: UHNWI / Families | G12: London | H12: Through customer | I12: Cleared
